[     1.558][MainProcess][INFO] Parsing specification...
[     1.562][MainProcess][DEBUG] Reading input files...
Traceback (most recent call last):
  File "./cubes.py", line 95, in <module>
    main()
  File "./cubes.py", line 68, in main
    specification = Specification(spec)
  File "/home/rmbb/CUBES/squares/dsl/specification.py", line 101, in __init__
    df = read_table(input)
  File "/home/rmbb/CUBES/squares/dsl/specification.py", line 24, in read_table
    df = pandas.read_csv(path)
  File "/home/rmbb/anaconda3/envs/squares/lib/python3.8/site-packages/pandas/io/parsers.py", line 676, in parser_f
    return _read(filepath_or_buffer, kwds)
  File "/home/rmbb/anaconda3/envs/squares/lib/python3.8/site-packages/pandas/io/parsers.py", line 448, in _read
    parser = TextFileReader(fp_or_buf, **kwds)
  File "/home/rmbb/anaconda3/envs/squares/lib/python3.8/site-packages/pandas/io/parsers.py", line 880, in __init__
    self._make_engine(self.engine)
  File "/home/rmbb/anaconda3/envs/squares/lib/python3.8/site-packages/pandas/io/parsers.py", line 1114, in _make_engine
    self._engine = CParserWrapper(self.f, **self.options)
  File "/home/rmbb/anaconda3/envs/squares/lib/python3.8/site-packages/pandas/io/parsers.py", line 1891, in __init__
    self._reader = parsers.TextReader(src, **kwds)
  File "pandas/_libs/parsers.pyx", line 374, in pandas._libs.parsers.TextReader.__cinit__
  File "pandas/_libs/parsers.pyx", line 674, in pandas._libs.parsers.TextReader._setup_parser_source
FileNotFoundError: [Errno 2] File tests-examples/scythe/recent_posts/tables/041.csv does not exist: 'tests-examples/scythe/recent_posts/tables/041.csv'
